[2025-10-17T20:36:27.396+0000] {taskinstance.py:1157} INFO - Dependencies all met for dep_context=non-requeueable deps ti=<TaskInstance: dbt_run_pipeline.dbt_run manual__2025-10-17T20:36:18.256673+00:00 [queued]>
[2025-10-17T20:36:27.409+0000] {taskinstance.py:1157} INFO - Dependencies all met for dep_context=requeueable deps ti=<TaskInstance: dbt_run_pipeline.dbt_run manual__2025-10-17T20:36:18.256673+00:00 [queued]>
[2025-10-17T20:36:27.410+0000] {taskinstance.py:1359} INFO - Starting attempt 1 of 1
[2025-10-17T20:36:27.432+0000] {taskinstance.py:1380} INFO - Executing <Task(BashOperator): dbt_run> on 2025-10-17 20:36:18.256673+00:00
[2025-10-17T20:36:27.436+0000] {standard_task_runner.py:57} INFO - Started process 219 to run task
[2025-10-17T20:36:27.439+0000] {standard_task_runner.py:84} INFO - Running: ['***', 'tasks', 'run', 'dbt_run_pipeline', 'dbt_run', 'manual__2025-10-17T20:36:18.256673+00:00', '--job-id', '7', '--raw', '--subdir', 'DAGS_FOLDER/dbt_dag.py', '--cfg-path', '/tmp/tmpk51_w5qa']
[2025-10-17T20:36:27.443+0000] {standard_task_runner.py:85} INFO - Job 7: Subtask dbt_run
[2025-10-17T20:36:27.460+0000] {logging_mixin.py:151} WARNING - /home/***/.local/lib/python3.11/site-packages/***/settings.py:195 DeprecationWarning: The sql_alchemy_conn option in [core] has been moved to the sql_alchemy_conn option in [database] - the old setting has been used, but please update your config.
[2025-10-17T20:36:27.505+0000] {task_command.py:415} INFO - Running <TaskInstance: dbt_run_pipeline.dbt_run manual__2025-10-17T20:36:18.256673+00:00 [running]> on host 00b52ae6051a
[2025-10-17T20:36:27.577+0000] {taskinstance.py:1660} INFO - Exporting env vars: AIRFLOW_CTX_DAG_OWNER='***' AIRFLOW_CTX_DAG_ID='dbt_run_pipeline' AIRFLOW_CTX_TASK_ID='dbt_run' AIRFLOW_CTX_EXECUTION_DATE='2025-10-17T20:36:18.256673+00:00' AIRFLOW_CTX_TRY_NUMBER='1' AIRFLOW_CTX_DAG_RUN_ID='manual__2025-10-17T20:36:18.256673+00:00'
[2025-10-17T20:36:27.579+0000] {subprocess.py:63} INFO - Tmp dir root location: /tmp
[2025-10-17T20:36:27.580+0000] {subprocess.py:75} INFO - Running command: ['/bin/bash', '-c', 'cd /opt/***/dbt_project && dbt run --profiles-dir .']
[2025-10-17T20:36:27.589+0000] {subprocess.py:86} INFO - Output:
[2025-10-17T20:36:27.591+0000] {subprocess.py:93} INFO - /bin/bash: line 1: cd: /opt/***/dbt_project: No such file or directory
[2025-10-17T20:36:27.591+0000] {subprocess.py:97} INFO - Command exited with return code 1
[2025-10-17T20:36:27.603+0000] {taskinstance.py:1935} ERROR - Task failed with exception
Traceback (most recent call last):
  File "/home/airflow/.local/lib/python3.11/site-packages/airflow/operators/bash.py", line 210, in execute
    raise AirflowException(
airflow.exceptions.AirflowException: Bash command failed. The command returned a non-zero exit code 1.
[2025-10-17T20:36:27.607+0000] {taskinstance.py:1398} INFO - Marking task as FAILED. dag_id=dbt_run_pipeline, task_id=dbt_run, execution_date=20251017T203618, start_date=20251017T203627, end_date=20251017T203627
[2025-10-17T20:36:27.618+0000] {standard_task_runner.py:104} ERROR - Failed to execute job 7 for task dbt_run (Bash command failed. The command returned a non-zero exit code 1.; 219)
[2025-10-17T20:36:27.660+0000] {local_task_job_runner.py:228} INFO - Task exited with return code 1
[2025-10-17T20:36:27.687+0000] {taskinstance.py:2776} INFO - 0 downstream tasks scheduled from follow-on schedule check
