[2025-10-17T21:17:08.255+0000] {taskinstance.py:1157} INFO - Dependencies all met for dep_context=non-requeueable deps ti=<TaskInstance: dbt_run_pipeline.dbt_init manual__2025-10-17T21:17:05.130390+00:00 [queued]>
[2025-10-17T21:17:08.264+0000] {taskinstance.py:1157} INFO - Dependencies all met for dep_context=requeueable deps ti=<TaskInstance: dbt_run_pipeline.dbt_init manual__2025-10-17T21:17:05.130390+00:00 [queued]>
[2025-10-17T21:17:08.265+0000] {taskinstance.py:1359} INFO - Starting attempt 1 of 1
[2025-10-17T21:17:08.277+0000] {taskinstance.py:1380} INFO - Executing <Task(BashOperator): dbt_init> on 2025-10-17 21:17:05.130390+00:00
[2025-10-17T21:17:08.283+0000] {standard_task_runner.py:57} INFO - Started process 188 to run task
[2025-10-17T21:17:08.287+0000] {standard_task_runner.py:84} INFO - Running: ['***', 'tasks', 'run', 'dbt_run_pipeline', 'dbt_init', 'manual__2025-10-17T21:17:05.130390+00:00', '--job-id', '28', '--raw', '--subdir', 'DAGS_FOLDER/dbt_dag.py', '--cfg-path', '/tmp/tmp225nwvd3']
[2025-10-17T21:17:08.291+0000] {standard_task_runner.py:85} INFO - Job 28: Subtask dbt_init
[2025-10-17T21:17:08.310+0000] {logging_mixin.py:151} WARNING - /home/***/.local/lib/python3.11/site-packages/***/settings.py:195 DeprecationWarning: The sql_alchemy_conn option in [core] has been moved to the sql_alchemy_conn option in [database] - the old setting has been used, but please update your config.
[2025-10-17T21:17:08.352+0000] {task_command.py:415} INFO - Running <TaskInstance: dbt_run_pipeline.dbt_init manual__2025-10-17T21:17:05.130390+00:00 [running]> on host 10529ec04042
[2025-10-17T21:17:08.443+0000] {taskinstance.py:1660} INFO - Exporting env vars: AIRFLOW_CTX_DAG_OWNER='***' AIRFLOW_CTX_DAG_ID='dbt_run_pipeline' AIRFLOW_CTX_TASK_ID='dbt_init' AIRFLOW_CTX_EXECUTION_DATE='2025-10-17T21:17:05.130390+00:00' AIRFLOW_CTX_TRY_NUMBER='1' AIRFLOW_CTX_DAG_RUN_ID='manual__2025-10-17T21:17:05.130390+00:00'
[2025-10-17T21:17:08.445+0000] {subprocess.py:63} INFO - Tmp dir root location: /tmp
[2025-10-17T21:17:08.446+0000] {subprocess.py:75} INFO - Running command: ['/bin/bash', '-c', 'cd /opt/***/dbt && dbt debug --profiles-dir . || true']
[2025-10-17T21:17:08.455+0000] {subprocess.py:86} INFO - Output:
[2025-10-17T21:17:11.491+0000] {subprocess.py:93} INFO - [0m21:17:11  Running with dbt=1.7.0
[2025-10-17T21:17:11.492+0000] {subprocess.py:93} INFO - [0m21:17:11  dbt version: 1.7.0
[2025-10-17T21:17:11.493+0000] {subprocess.py:93} INFO - [0m21:17:11  python version: 3.11.5
[2025-10-17T21:17:11.494+0000] {subprocess.py:93} INFO - [0m21:17:11  python path: /usr/local/bin/python
[2025-10-17T21:17:11.495+0000] {subprocess.py:93} INFO - [0m21:17:11  os info: Linux-6.10.14-linuxkit-x86_64-with-glibc2.31
[2025-10-17T21:17:11.652+0000] {subprocess.py:93} INFO - [0m21:17:11  Using profiles dir at .
[2025-10-17T21:17:11.653+0000] {subprocess.py:93} INFO - [0m21:17:11  Using profiles.yml file at ./profiles.yml
[2025-10-17T21:17:11.653+0000] {subprocess.py:93} INFO - [0m21:17:11  Using dbt_project.yml file at /opt/***/dbt/dbt_project.yml
[2025-10-17T21:17:11.654+0000] {subprocess.py:93} INFO - [0m21:17:11  adapter type: postgres
[2025-10-17T21:17:11.655+0000] {subprocess.py:93} INFO - [0m21:17:11  adapter version: 1.7.0
[2025-10-17T21:17:11.744+0000] {subprocess.py:93} INFO - [0m21:17:11  Configuration:
[2025-10-17T21:17:11.745+0000] {subprocess.py:93} INFO - [0m21:17:11    profiles.yml file [[32mOK found and valid[0m]
[2025-10-17T21:17:11.746+0000] {subprocess.py:93} INFO - [0m21:17:11    dbt_project.yml file [[32mOK found and valid[0m]
[2025-10-17T21:17:11.747+0000] {subprocess.py:93} INFO - [0m21:17:11  Required dependencies:
[2025-10-17T21:17:11.750+0000] {subprocess.py:93} INFO - [0m21:17:11   - git [[31mERROR[0m]
[2025-10-17T21:17:11.751+0000] {subprocess.py:93} INFO - 
[2025-10-17T21:17:11.751+0000] {subprocess.py:93} INFO - [0m21:17:11  Connection:
[2025-10-17T21:17:11.752+0000] {subprocess.py:93} INFO - [0m21:17:11    host: postgres
[2025-10-17T21:17:11.754+0000] {subprocess.py:93} INFO - [0m21:17:11    port: 5432
[2025-10-17T21:17:11.755+0000] {subprocess.py:93} INFO - [0m21:17:11    user: ***
[2025-10-17T21:17:11.756+0000] {subprocess.py:93} INFO - [0m21:17:11    database: ***
[2025-10-17T21:17:11.756+0000] {subprocess.py:93} INFO - [0m21:17:11    schema: public
[2025-10-17T21:17:11.757+0000] {subprocess.py:93} INFO - [0m21:17:11    connect_timeout: 10
[2025-10-17T21:17:11.758+0000] {subprocess.py:93} INFO - [0m21:17:11    role: None
[2025-10-17T21:17:11.759+0000] {subprocess.py:93} INFO - [0m21:17:11    search_path: None
[2025-10-17T21:17:11.760+0000] {subprocess.py:93} INFO - [0m21:17:11    keepalives_idle: 0
[2025-10-17T21:17:11.761+0000] {subprocess.py:93} INFO - [0m21:17:11    sslmode: None
[2025-10-17T21:17:11.762+0000] {subprocess.py:93} INFO - [0m21:17:11    sslcert: None
[2025-10-17T21:17:11.763+0000] {subprocess.py:93} INFO - [0m21:17:11    sslkey: None
[2025-10-17T21:17:11.764+0000] {subprocess.py:93} INFO - [0m21:17:11    sslrootcert: None
[2025-10-17T21:17:11.765+0000] {subprocess.py:93} INFO - [0m21:17:11    application_name: dbt
[2025-10-17T21:17:11.766+0000] {subprocess.py:93} INFO - [0m21:17:11    retries: 1
[2025-10-17T21:17:11.767+0000] {subprocess.py:93} INFO - [0m21:17:11  Registered adapter: postgres=1.7.0
[2025-10-17T21:17:11.787+0000] {subprocess.py:93} INFO - [0m21:17:11    Connection test: [[32mOK connection ok[0m]
[2025-10-17T21:17:11.787+0000] {subprocess.py:93} INFO - 
[2025-10-17T21:17:11.788+0000] {subprocess.py:93} INFO - [0m21:17:11  [31m1 check failed:[0m
[2025-10-17T21:17:11.789+0000] {subprocess.py:93} INFO - [0m21:17:11  Error from git --help: User does not have permissions for this command: "git"
[2025-10-17T21:17:11.789+0000] {subprocess.py:93} INFO - 
[2025-10-17T21:17:12.812+0000] {subprocess.py:97} INFO - Command exited with return code 0
[2025-10-17T21:17:12.839+0000] {taskinstance.py:1398} INFO - Marking task as SUCCESS. dag_id=dbt_run_pipeline, task_id=dbt_init, execution_date=20251017T211705, start_date=20251017T211708, end_date=20251017T211712
[2025-10-17T21:17:12.895+0000] {local_task_job_runner.py:228} INFO - Task exited with return code 0
[2025-10-17T21:17:12.925+0000] {taskinstance.py:2776} INFO - 1 downstream tasks scheduled from follow-on schedule check
