[2025-10-16T13:28:12.950+0000] {taskinstance.py:1157} INFO - Dependencies all met for dep_context=non-requeueable deps ti=<TaskInstance: dbt_run_pipeline.dbt_seed scheduled__2025-10-15T00:00:00+00:00 [queued]>
[2025-10-16T13:28:12.961+0000] {taskinstance.py:1157} INFO - Dependencies all met for dep_context=requeueable deps ti=<TaskInstance: dbt_run_pipeline.dbt_seed scheduled__2025-10-15T00:00:00+00:00 [queued]>
[2025-10-16T13:28:12.962+0000] {taskinstance.py:1359} INFO - Starting attempt 1 of 1
[2025-10-16T13:28:12.978+0000] {taskinstance.py:1380} INFO - Executing <Task(BashOperator): dbt_seed> on 2025-10-15 00:00:00+00:00
[2025-10-16T13:28:12.985+0000] {standard_task_runner.py:57} INFO - Started process 183 to run task
[2025-10-16T13:28:12.989+0000] {standard_task_runner.py:84} INFO - Running: ['***', 'tasks', 'run', 'dbt_run_pipeline', 'dbt_seed', 'scheduled__2025-10-15T00:00:00+00:00', '--job-id', '5', '--raw', '--subdir', 'DAGS_FOLDER/dbt_dag.py', '--cfg-path', '/tmp/tmpml1zqdta']
[2025-10-16T13:28:12.993+0000] {standard_task_runner.py:85} INFO - Job 5: Subtask dbt_seed
[2025-10-16T13:28:13.052+0000] {logging_mixin.py:151} WARNING - /home/***/.local/lib/python3.11/site-packages/***/settings.py:195 DeprecationWarning: The sql_alchemy_conn option in [core] has been moved to the sql_alchemy_conn option in [database] - the old setting has been used, but please update your config.
[2025-10-16T13:28:13.111+0000] {task_command.py:415} INFO - Running <TaskInstance: dbt_run_pipeline.dbt_seed scheduled__2025-10-15T00:00:00+00:00 [running]> on host 2e5e3d4f13d1
[2025-10-16T13:28:13.217+0000] {taskinstance.py:1660} INFO - Exporting env vars: AIRFLOW_CTX_DAG_OWNER='***' AIRFLOW_CTX_DAG_ID='dbt_run_pipeline' AIRFLOW_CTX_TASK_ID='dbt_seed' AIRFLOW_CTX_EXECUTION_DATE='2025-10-15T00:00:00+00:00' AIRFLOW_CTX_TRY_NUMBER='1' AIRFLOW_CTX_DAG_RUN_ID='scheduled__2025-10-15T00:00:00+00:00'
[2025-10-16T13:28:13.219+0000] {subprocess.py:63} INFO - Tmp dir root location: /tmp
[2025-10-16T13:28:13.221+0000] {subprocess.py:75} INFO - Running command: ['/bin/bash', '-c', 'cd /opt/***/dbt_project && dbt seed --profiles-dir .']
[2025-10-16T13:28:13.234+0000] {subprocess.py:86} INFO - Output:
[2025-10-16T13:28:13.237+0000] {subprocess.py:93} INFO - /bin/bash: line 1: cd: /opt/***/dbt_project: No such file or directory
[2025-10-16T13:28:13.238+0000] {subprocess.py:97} INFO - Command exited with return code 1
[2025-10-16T13:28:13.252+0000] {taskinstance.py:1935} ERROR - Task failed with exception
Traceback (most recent call last):
  File "/home/airflow/.local/lib/python3.11/site-packages/airflow/operators/bash.py", line 210, in execute
    raise AirflowException(
airflow.exceptions.AirflowException: Bash command failed. The command returned a non-zero exit code 1.
[2025-10-16T13:28:13.258+0000] {taskinstance.py:1398} INFO - Marking task as FAILED. dag_id=dbt_run_pipeline, task_id=dbt_seed, execution_date=20251015T000000, start_date=20251016T132812, end_date=20251016T132813
[2025-10-16T13:28:13.277+0000] {standard_task_runner.py:104} ERROR - Failed to execute job 5 for task dbt_seed (Bash command failed. The command returned a non-zero exit code 1.; 183)
[2025-10-16T13:28:13.313+0000] {local_task_job_runner.py:228} INFO - Task exited with return code 1
[2025-10-16T13:28:13.350+0000] {taskinstance.py:2776} INFO - 0 downstream tasks scheduled from follow-on schedule check
