[2025-10-17T20:11:30.745+0000] {taskinstance.py:1157} INFO - Dependencies all met for dep_context=non-requeueable deps ti=<TaskInstance: dbt_run_pipeline.dbt_seed manual__2025-10-17T20:11:27.506384+00:00 [queued]>
[2025-10-17T20:11:30.757+0000] {taskinstance.py:1157} INFO - Dependencies all met for dep_context=requeueable deps ti=<TaskInstance: dbt_run_pipeline.dbt_seed manual__2025-10-17T20:11:27.506384+00:00 [queued]>
[2025-10-17T20:11:30.758+0000] {taskinstance.py:1359} INFO - Starting attempt 1 of 1
[2025-10-17T20:11:30.773+0000] {taskinstance.py:1380} INFO - Executing <Task(BashOperator): dbt_seed> on 2025-10-17 20:11:27.506384+00:00
[2025-10-17T20:11:30.778+0000] {standard_task_runner.py:57} INFO - Started process 237 to run task
[2025-10-17T20:11:30.782+0000] {standard_task_runner.py:84} INFO - Running: ['***', 'tasks', 'run', 'dbt_run_pipeline', 'dbt_seed', 'manual__2025-10-17T20:11:27.506384+00:00', '--job-id', '5', '--raw', '--subdir', 'DAGS_FOLDER/dbt_dag.py', '--cfg-path', '/tmp/tmp2rgyblmf']
[2025-10-17T20:11:30.786+0000] {standard_task_runner.py:85} INFO - Job 5: Subtask dbt_seed
[2025-10-17T20:11:30.807+0000] {logging_mixin.py:151} WARNING - /home/***/.local/lib/python3.11/site-packages/***/settings.py:195 DeprecationWarning: The sql_alchemy_conn option in [core] has been moved to the sql_alchemy_conn option in [database] - the old setting has been used, but please update your config.
[2025-10-17T20:11:30.853+0000] {task_command.py:415} INFO - Running <TaskInstance: dbt_run_pipeline.dbt_seed manual__2025-10-17T20:11:27.506384+00:00 [running]> on host 73cb6ab1cd9d
[2025-10-17T20:11:30.960+0000] {taskinstance.py:1660} INFO - Exporting env vars: AIRFLOW_CTX_DAG_OWNER='***' AIRFLOW_CTX_DAG_ID='dbt_run_pipeline' AIRFLOW_CTX_TASK_ID='dbt_seed' AIRFLOW_CTX_EXECUTION_DATE='2025-10-17T20:11:27.506384+00:00' AIRFLOW_CTX_TRY_NUMBER='1' AIRFLOW_CTX_DAG_RUN_ID='manual__2025-10-17T20:11:27.506384+00:00'
[2025-10-17T20:11:30.964+0000] {subprocess.py:63} INFO - Tmp dir root location: /tmp
[2025-10-17T20:11:30.966+0000] {subprocess.py:75} INFO - Running command: ['/bin/bash', '-c', 'cd /opt/***/dbt_project && dbt seed --profiles-dir .']
[2025-10-17T20:11:30.980+0000] {subprocess.py:86} INFO - Output:
[2025-10-17T20:11:30.982+0000] {subprocess.py:93} INFO - /bin/bash: line 1: cd: /opt/***/dbt_project: No such file or directory
[2025-10-17T20:11:30.983+0000] {subprocess.py:97} INFO - Command exited with return code 1
[2025-10-17T20:11:30.996+0000] {taskinstance.py:1935} ERROR - Task failed with exception
Traceback (most recent call last):
  File "/home/airflow/.local/lib/python3.11/site-packages/airflow/operators/bash.py", line 210, in execute
    raise AirflowException(
airflow.exceptions.AirflowException: Bash command failed. The command returned a non-zero exit code 1.
[2025-10-17T20:11:31.001+0000] {taskinstance.py:1398} INFO - Marking task as FAILED. dag_id=dbt_run_pipeline, task_id=dbt_seed, execution_date=20251017T201127, start_date=20251017T201130, end_date=20251017T201131
[2025-10-17T20:11:31.014+0000] {standard_task_runner.py:104} ERROR - Failed to execute job 5 for task dbt_seed (Bash command failed. The command returned a non-zero exit code 1.; 237)
[2025-10-17T20:11:31.043+0000] {local_task_job_runner.py:228} INFO - Task exited with return code 1
[2025-10-17T20:11:31.073+0000] {taskinstance.py:2776} INFO - 0 downstream tasks scheduled from follow-on schedule check
